#VRML_SIM R2023b utf8

EXTERNPROTO "https://raw.githubusercontent.com/cyberbotics/webots/R2023b/projects/objects/backgrounds/protos/TexturedBackground.proto"
EXTERNPROTO "https://raw.githubusercontent.com/cyberbotics/webots/R2023b/projects/objects/backgrounds/protos/TexturedBackgroundLight.proto"
EXTERNPROTO "https://raw.githubusercontent.com/cyberbotics/webots/R2023b/projects/objects/floors/protos/RectangleArena.proto"
EXTERNPROTO "https://raw.githubusercontent.com/cyberbotics/webots/R2023b/projects/appearances/protos/BrushedAluminium.proto"
EXTERNPROTO "https://raw.githubusercontent.com/cyberbotics/webots/R2023b/projects/samples/contests/robocup/protos/RobocupSoccerField.proto"

WorldInfo {
  info [
    "Thanks to Mehdi Ghanavati, Shahid Chamran University"
  ]
  title "Omni-wheels"
  basicTimeStep 8
}
Viewpoint {
  orientation -0.1518553764864252 -0.9264498833936208 0.344427870812036 5.394562782976485
  position -3.159178557731706 0.07199359216303432 5.180670112494429
}
TexturedBackground {
}
TexturedBackgroundLight {
}
RectangleArena {
  floorSize 11 8
  wallAppearance BrushedAluminium {
    colorOverride 0 0 0
  }
}
RobocupSoccerField {
  size "kid"
}
DEF OMNI_WHEELS_4 Robot {
  translation 1.64439 1.24795 0.06
  rotation 0.0008646924717782624 -2.7749156625345907e-05 0.9999996257683869 0.8373773005898107
  children [
    InertialUnit {
      name "IMU"
    }
    DEF SOLID1 Solid {
      rotation 0 0 1 0.7854003061004253
      children [
        DEF WHEEL1 HingeJoint {
          jointParameters HingeJointParameters {
            position 39.266952503063855
            anchor -0.1 0 0
          }
          device [
            RotationalMotor {
              name "wheel3"
            }
            PositionSensor {
              name "pw3"
            }
          ]
          endPoint Solid {
            translation -0.18799999999756062 -1.2929122714678933e-05 3.872408684111886e-08
            rotation 0.9999999999995569 6.666612978759893e-07 6.646418641983545e-07 1.5678407648645984
            children [
              DEF sr1 HingeJoint {
                jointParameters HingeJointParameters {
                  position -126.31835906130954
                  axis 0 1 0
                  anchor -0.02 0 0.05
                }
                endPoint Solid {
                  translation -0.02 0 0.05
                  rotation 0 -1 0 0.6546529177178064
                  children [
                    DEF r1 Pose {
                      rotation -1 0 0 1.5708
                      children [
                        DEF SMALL_WHEEL_SHAPE Shape {
                          appearance PBRAppearance {
                            baseColor 1 0.752941 0.796078
                            roughness 1
                            metalness 0
                          }
                          geometry Cylinder {
                            height 0.02
                            radius 0.01
                          }
                        }
                      ]
                    }
                  ]
                  name "sr1"
                  boundingObject USE r1
                  physics Physics {
                    density -1
                    mass 0.1
                  }
                }
              }
              DEF sr2 HingeJoint {
                jointParameters HingeJointParameters {
                  position 145.23893767255893
                  axis 0 -0.707107 0.707107
                  anchor -0.02 0.03535 0.03535
                }
                endPoint Solid {
                  translation -0.02 0.03535 0.03535
                  rotation 0 0.7071067811865475 -0.7071067811865475 5.557509699751143
                  children [
                    DEF r2 Pose {
                      rotation -1 0 0 2.27
                      children [
                        USE SMALL_WHEEL_SHAPE
                      ]
                    }
                  ]
                  name "sr2"
                  boundingObject USE r2
                  physics Physics {
                    density -1
                    mass 0.1
                  }
                }
              }
              DEF sr3 HingeJoint {
                jointParameters HingeJointParameters {
                  position 315.6244942672359
                  axis 0 1 0
                  anchor -0.02 0 -0.05
                }
                endPoint Solid {
                  translation -0.02 0 -0.05
                  rotation 0 1 0 1.4652289082565648
                  children [
                    DEF r3 Pose {
                      rotation -1 0 0 1.5708
                      children [
                        USE SMALL_WHEEL_SHAPE
                      ]
                    }
                  ]
                  name "sr3"
                  boundingObject USE r3
                  physics Physics {
                    density -1
                    mass 0.1
                  }
                }
              }
              DEF sr4 HingeJoint {
                jointParameters HingeJointParameters {
                  position -195.38430891061194
                  axis 0 -0.707107 0.707107
                  anchor -0.02 -0.03535 -0.03535
                }
                endPoint Solid {
                  translation -0.02 -0.03535 -0.03535
                  rotation 0 -0.7071067811865475 0.7071067811865475 5.677620919134832
                  children [
                    DEF r4 Pose {
                      rotation -1 0 0 2.27
                      children [
                        USE SMALL_WHEEL_SHAPE
                      ]
                    }
                  ]
                  name "sr4"
                  boundingObject USE r4
                  physics Physics {
                    density -1
                    mass 0.1
                  }
                }
              }
              DEF sr5 HingeJoint {
                jointParameters HingeJointParameters {
                  position 147.55102902190777
                  axis 0 0 1
                  anchor -0.02 0.05 0
                }
                endPoint Solid {
                  translation -0.02 0.05 0
                  rotation 0 0 -1 3.2454183504023093
                  children [
                    DEF r5 Pose {
                      children [
                        USE SMALL_WHEEL_SHAPE
                      ]
                    }
                  ]
                  name "sr5"
                  boundingObject USE r5
                  physics Physics {
                    density -1
                    mass 0.1
                  }
                }
              }
              DEF sr6 HingeJoint {
                jointParameters HingeJointParameters {
                  position -154.2668776251037
                  axis 0 0 1
                  anchor -0.02 -0.05 0
                }
                endPoint Solid {
                  translation -0.02 -0.05 0
                  rotation 0 0 -1 3.4704302527936135
                  children [
                    DEF r6 Pose {
                      children [
                        USE SMALL_WHEEL_SHAPE
                      ]
                    }
                  ]
                  name "sr6"
                  boundingObject USE r6
                  physics Physics {
                    density -1
                    mass 0.1
                  }
                }
              }
              DEF sr7 HingeJoint {
                jointParameters HingeJointParameters {
                  position 179.56148084276518
                  axis 0 0.707107 0.707107
                  anchor -0.02 0.03535 -0.03535
                }
                endPoint Solid {
                  translation -0.02 0.03535 -0.03535
                  rotation 0 0.7071067811865476 0.7071067811865476 3.632292241736757
                  children [
                    DEF r7 Pose {
                      rotation -1 0 0 0.76
                      children [
                        USE SMALL_WHEEL_SHAPE
                      ]
                    }
                  ]
                  name "sr7"
                  boundingObject USE r7
                  physics Physics {
                    density -1
                    mass 0.1
                  }
                }
              }
              DEF sr8 HingeJoint {
                jointParameters HingeJointParameters {
                  position -151.50952450734218
                  axis 0 0.707107 0.707107
                  anchor -0.02 -0.03535 0.03535
                }
                endPoint Solid {
                  translation -0.02 -0.03535 0.03535
                  rotation 0 -0.7071067811865476 -0.7071067811865476 0.7130771350321022
                  children [
                    DEF r8 Pose {
                      rotation -1 0 0 0.76
                      children [
                        USE SMALL_WHEEL_SHAPE
                      ]
                    }
                  ]
                  name "sr8"
                  boundingObject USE r8
                  physics Physics {
                    density -1
                    mass 0.1
                  }
                }
              }
              DEF WHEEL_TRANS Pose {
                translation -0.02 0 0
                rotation 0 -1 0 1.5708
                children [
                  DEF WHEEL_SHAPE Shape {
                    appearance PBRAppearance {
                      baseColor 0.678431 0.847059 0.901961
                      roughness 1
                      metalness 0
                    }
                    geometry Cylinder {
                      height 0.02
                      radius 0.05
                      subdivision 20
                    }
                  }
                ]
              }
            ]
            boundingObject Pose {
              translation -0.02 0 0
              rotation 0 -1 0 1.5708
              children [
                DEF wheel1 Shape {
                  appearance PBRAppearance {
                    baseColor 0.8 0.8 0.8
                    transparency 0.12999999523162842
                    roughness 1
                    metalness 0
                    emissiveColor 0 1 0
                  }
                  geometry Cylinder {
                    height 0.02
                    radius 0.05
                  }
                }
              ]
            }
            physics Physics {
            }
          }
        }
      ]
      name "wheel 1"
      boundingObject DEF DUMMY Sphere {
        radius 0.01
      }
      physics Physics {
      }
    }
    DEF SOLID2 Solid {
      rotation 0 0 1 2.3561996938995744
      children [
        DEF WHEEL2 HingeJoint {
          jointParameters HingeJointParameters {
            position 39.26695940667728
            anchor -0.1 0 0
          }
          device [
            RotationalMotor {
              name "wheel4"
            }
            PositionSensor {
              name "pw4"
            }
          ]
          endPoint Solid {
            translation -0.18800000004308107 -1.288918037647514e-05 3.743020158379229e-08
            rotation 0.999999999999522 6.914781373945531e-07 6.911653715994697e-07 1.5654417141275923
            children [
              DEF sr1 HingeJoint {
                jointParameters HingeJointParameters {
                  position 281.3285552745825
                  axis 0 1 0
                  anchor -0.02 0 0.05
                }
                endPoint Solid {
                  translation -0.02 0 0.05
                  rotation 0 1 0 4.868401758680722
                  children [
                    USE r1
                  ]
                  name "sr1"
                  boundingObject USE r1
                  physics Physics {
                    density -1
                    mass 0.1
                  }
                }
              }
              DEF sr2 HingeJoint {
                jointParameters HingeJointParameters {
                  position -654.5468091978694
                  axis 0 -0.707107 0.707107
                  anchor -0.02 0.03535 0.03535
                }
                endPoint Solid {
                  translation -0.02 0.03535 0.03535
                  rotation 0 0.7071067811865476 -0.7071067811865476 1.0955372511923858
                  children [
                    USE r2
                  ]
                  name "sr2"
                  boundingObject USE r2
                  physics Physics {
                    density -1
                    mass 0.1
                  }
                }
              }
              DEF sr3 HingeJoint {
                jointParameters HingeJointParameters {
                  position -301.8412982122163
                  axis 0 1 0
                  anchor -0.02 0 -0.05
                }
                endPoint Solid {
                  translation -0.02 0 -0.05
                  rotation 0 -1 0 0.24840346759616405
                  children [
                    USE r3
                  ]
                  name "sr3"
                  boundingObject USE r3
                  physics Physics {
                    density -1
                    mass 0.1
                  }
                }
              }
              DEF sr4 HingeJoint {
                jointParameters HingeJointParameters {
                  position 498.1892944275055
                  axis 0 -0.707107 0.707107
                  anchor -0.02 -0.03535 -0.03535
                }
                endPoint Solid {
                  translation -0.02 -0.03535 -0.03535
                  rotation 0 0.7071067811865476 -0.7071067811865476 4.465530146861417
                  children [
                    USE r4
                  ]
                  name "sr4"
                  boundingObject USE r4
                  physics Physics {
                    density -1
                    mass 0.1
                  }
                }
              }
              DEF sr5 HingeJoint {
                jointParameters HingeJointParameters {
                  position -315.6834546224356
                  axis 0 0 1
                  anchor -0.02 0.05 0
                }
                endPoint Solid {
                  translation -0.02 0.05 0
                  rotation 0 0 -1 1.5241892634562664
                  children [
                    USE r5
                  ]
                  name "sr5"
                  boundingObject USE r5
                  physics Physics {
                    density -1
                    mass 0.1
                  }
                }
              }
              DEF sr6 HingeJoint {
                jointParameters HingeJointParameters {
                  position 573.459968285009
                  axis 0 0 1
                  anchor -0.02 -0.05 0
                }
                endPoint Solid {
                  translation -0.02 -0.05 0
                  rotation 0 0 -1 4.593079975512915
                  children [
                    USE r6
                  ]
                  name "sr6"
                  boundingObject USE r6
                  physics Physics {
                    density -1
                    mass 0.1
                  }
                }
              }
              DEF sr7 HingeJoint {
                jointParameters HingeJointParameters {
                  position -638.5444875606736
                  axis 0 0.707107 0.707107
                  anchor -0.02 0.03535 -0.03535
                }
                endPoint Solid {
                  translation -0.02 0.03535 -0.03535
                  rotation 0 0.7071067811865475 0.7071067811865475 2.340413771644233
                  children [
                    USE r7
                  ]
                  name "sr7"
                  boundingObject USE r7
                  physics Physics {
                    density -1
                    mass 0.1
                  }
                }
              }
              DEF sr8 HingeJoint {
                jointParameters HingeJointParameters {
                  position 452.924878582051
                  axis 0 0.707107 0.707107
                  anchor -0.02 -0.03535 0.03535
                }
                endPoint Solid {
                  translation -0.02 -0.03535 0.03535
                  rotation 0 0.7071067811865476 0.7071067811865476 0.5355364651207812
                  children [
                    USE r8
                  ]
                  name "sr8"
                  boundingObject USE r8
                  physics Physics {
                    density -1
                    mass 0.1
                  }
                }
              }
              USE WHEEL_TRANS
            ]
            boundingObject Pose {
              translation -0.02 0 0
              rotation 0 -1 0 1.5708
              children [
                DEF wheel1 Shape {
                  appearance PBRAppearance {
                    baseColor 0.8 0.8 0.8
                    transparency 0.12999999523162842
                    roughness 1
                    metalness 0
                    emissiveColor 0 1 0
                  }
                  geometry Cylinder {
                    height 0.02
                    radius 0.05
                  }
                }
              ]
            }
            physics Physics {
            }
          }
        }
      ]
      name "wheel 2"
      boundingObject USE DUMMY
      physics Physics {
      }
    }
    DEF SOLID3 Solid {
      rotation 0 0 1 -2.3561950010791604
      children [
        DEF WHEEL3 HingeJoint {
          jointParameters HingeJointParameters {
            position -38.62730686243758
            anchor -0.1 0 0
          }
          device [
            PositionSensor {
              name "pw1"
            }
            RotationalMotor {
              name "wheel1"
            }
          ]
          endPoint Solid {
            translation -0.187999999989864 1.0334342591741564e-05 7.735468730047316e-06
            rotation -0.9999999999988193 1.3754176449867172e-06 -6.852057733274673e-07 0.9321031327763781
            children [
              DEF sr1 HingeJoint {
                jointParameters HingeJointParameters {
                  position 210.872298479945
                  axis 0 1 0
                  anchor -0.02 0 0.05
                }
                endPoint Solid {
                  translation -0.02 0 0.05
                  rotation 0 -1 0 2.7560019641609528
                  children [
                    USE r1
                  ]
                  name "sr1"
                  boundingObject USE r1
                  physics Physics {
                    density -1
                    mass 0.1
                  }
                }
              }
              DEF sr2 HingeJoint {
                jointParameters HingeJointParameters {
                  position -524.168522009818
                  axis 0 -0.707107 0.707107
                  anchor -0.02 0.03535 0.03535
                }
                endPoint Solid {
                  translation -0.02 0.03535 0.03535
                  rotation 0 -0.7071067811865476 0.7071067811865476 3.619043793267216
                  children [
                    USE r2
                  ]
                  name "sr2"
                  boundingObject USE r2
                  physics Physics {
                    density -1
                    mass 0.1
                  }
                }
              }
              DEF sr3 HingeJoint {
                jointParameters HingeJointParameters {
                  position -294.03444192748987
                  axis 0 1 0
                  anchor -0.02 0 -0.05
                }
                endPoint Solid {
                  translation -0.02 0 -0.05
                  rotation 0 -0.9999999999999999 0 5.007917797228888
                  children [
                    USE r3
                  ]
                  name "sr3"
                  boundingObject USE r3
                  physics Physics {
                    density -1
                    mass 0.1
                  }
                }
              }
              DEF sr4 HingeJoint {
                jointParameters HingeJointParameters {
                  position 745.1436077755648
                  axis 0 -0.707107 0.707107
                  anchor -0.02 -0.03535 -0.03535
                }
                endPoint Solid {
                  translation -0.02 -0.03535 -0.03535
                  rotation 0 -0.7071067811865475 0.7071067811865475 3.727741528373556
                  children [
                    USE r4
                  ]
                  name "sr4"
                  boundingObject USE r4
                  physics Physics {
                    density -1
                    mass 0.1
                  }
                }
              }
              DEF sr5 HingeJoint {
                jointParameters HingeJointParameters {
                  position -164.32123279850606
                  axis 0 0 1
                  anchor -0.02 0.05 0
                }
                endPoint Solid {
                  translation -0.02 0.05 0
                  rotation 0 0 -1 0.958414811836811
                  children [
                    USE r5
                  ]
                  name "sr5"
                  boundingObject USE r5
                  physics Physics {
                    density -1
                    mass 0.1
                  }
                }
              }
              DEF sr6 HingeJoint {
                jointParameters HingeJointParameters {
                  position 273.9872641320462
                  axis 0 0 1
                  anchor -0.02 -0.05 0
                }
                endPoint Solid {
                  translation -0.02 -0.05 0
                  rotation 0 0 -1 2.472889383855584
                  children [
                    USE r6
                  ]
                  name "sr6"
                  boundingObject USE r6
                  physics Physics {
                    density -1
                    mass 0.1
                  }
                }
              }
              DEF sr7 HingeJoint {
                jointParameters HingeJointParameters {
                  position -337.77185823006744
                  axis 0 0.707107 0.707107
                  anchor -0.02 0.03535 -0.03535
                }
                endPoint Solid {
                  translation -0.02 0.03535 -0.03535
                  rotation 0 0.7071067811865476 0.7071067811865476 1.5201483576302326
                  children [
                    USE r7
                  ]
                  name "sr7"
                  boundingObject USE r7
                  physics Physics {
                    density -1
                    mass 0.1
                  }
                }
              }
              DEF sr8 HingeJoint {
                jointParameters HingeJointParameters {
                  position 337.1902555850693
                  axis 0 0.707107 0.707107
                  anchor -0.02 -0.03535 0.03535
                }
                endPoint Solid {
                  translation -0.02 -0.03535 0.03535
                  rotation 0 -0.7071067811865476 -0.7071067811865476 2.101751002628389
                  children [
                    USE r8
                  ]
                  name "sr8"
                  boundingObject USE r8
                  physics Physics {
                    density -1
                    mass 0.1
                  }
                }
              }
              USE WHEEL_TRANS
            ]
            boundingObject Pose {
              translation -0.02 0 0
              rotation 0 -1 0 1.5708
              children [
                DEF wheel1 Shape {
                  appearance PBRAppearance {
                    baseColor 0.8 0.8 0.8
                    transparency 0.12999999523162842
                    roughness 1
                    metalness 0
                    emissiveColor 0 1 0
                  }
                  geometry Cylinder {
                    height 0.02
                    radius 0.05
                  }
                }
              ]
            }
            physics Physics {
            }
          }
        }
      ]
      name "wheel 3"
      boundingObject USE DUMMY
      physics Physics {
      }
    }
    DEF SOLID4 Solid {
      rotation 0 0 1 -0.7854003061004253
      children [
        DEF WHEEL4 HingeJoint {
          jointParameters HingeJointParameters {
            position -38.62730494897178
            anchor -0.1 0 0
          }
          device [
            PositionSensor {
              name "pw2"
            }
            RotationalMotor {
              name "wheel2"
            }
          ]
          endPoint Solid {
            translation -0.1879999999437038 1.0360237540559678e-05 7.756340433975863e-06
            rotation -0.9999999999988133 1.379020318643372e-06 -6.868437801051039e-07 0.9321012008713594
            children [
              DEF sr1 HingeJoint {
                jointParameters HingeJointParameters {
                  position -118.85385785222414
                  axis 0 1 0
                  anchor -0.02 0 0.05
                }
                endPoint Solid {
                  translation -0.02 0 0.05
                  rotation 0 -1 0 5.756522322991581
                  children [
                    USE r1
                  ]
                  name "sr1"
                  boundingObject USE r1
                  physics Physics {
                    density -1
                    mass 0.1
                  }
                }
              }
              DEF sr2 HingeJoint {
                jointParameters HingeJointParameters {
                  position -173.12609295492786
                  axis 0 -0.707107 0.707107
                  anchor -0.02 0.03535 0.03535
                }
                endPoint Solid {
                  translation -0.02 0.03535 0.03535
                  rotation 0 -0.7071067811865476 0.7071067811865476 2.803095646100566
                  children [
                    USE r2
                  ]
                  name "sr2"
                  boundingObject USE r2
                  physics Physics {
                    density -1
                    mass 0.1
                  }
                }
              }
              DEF sr3 HingeJoint {
                jointParameters HingeJointParameters {
                  position 106.13970904629721
                  axis 0 1 0
                  anchor -0.02 0 -0.05
                }
                endPoint Solid {
                  translation -0.02 0 -0.05
                  rotation 0 1 0 5.60874413142383
                  children [
                    USE r3
                  ]
                  name "sr3"
                  boundingObject USE r3
                  physics Physics {
                    density -1
                    mass 0.1
                  }
                }
              }
              DEF sr4 HingeJoint {
                jointParameters HingeJointParameters {
                  position 342.2477663359929
                  axis 0 -0.707107 0.707107
                  anchor -0.02 -0.03535 -0.03535
                }
                endPoint Solid {
                  translation -0.02 -0.03535 -0.03535
                  rotation 0 -0.7071067811865476 0.7071067811865476 2.9557597482952085
                  children [
                    USE r4
                  ]
                  name "sr4"
                  boundingObject USE r4
                  physics Physics {
                    density -1
                    mass 0.1
                  }
                }
              }
              DEF sr5 HingeJoint {
                jointParameters HingeJointParameters {
                  position 148.49656428673194
                  axis 0 0 1
                  anchor -0.02 0.05 0
                }
                endPoint Solid {
                  translation -0.02 0.05 0
                  rotation 0 0 -1 2.2998830855781365
                  children [
                    USE r5
                  ]
                  name "sr5"
                  boundingObject USE r5
                  physics Physics {
                    density -1
                    mass 0.1
                  }
                }
              }
              DEF sr6 HingeJoint {
                jointParameters HingeJointParameters {
                  position -136.8657522689867
                  axis 0 0 1
                  anchor -0.02 -0.05 0
                }
                endPoint Solid {
                  translation -0.02 -0.05 0
                  rotation 0 0 1 1.3643244889641917
                  children [
                    USE r6
                  ]
                  name "sr6"
                  boundingObject USE r6
                  physics Physics {
                    density -1
                    mass 0.1
                  }
                }
              }
              DEF sr7 HingeJoint {
                jointParameters HingeJointParameters {
                  position 12.543655424733462
                  axis 0 0.707107 0.707107
                  anchor -0.02 0.03535 -0.03535
                }
                endPoint Solid {
                  translation -0.02 0.03535 -0.03535
                  rotation 0 -0.7071067811865476 -0.7071067811865476 0.02271518962571068
                  children [
                    USE r7
                  ]
                  name "sr7"
                  boundingObject USE r7
                  physics Physics {
                    density -1
                    mass 0.1
                  }
                }
              }
              DEF sr8 HingeJoint {
                jointParameters HingeJointParameters {
                  position -30.289988722133998
                  axis 0 0.707107 0.707107
                  anchor -0.02 -0.03535 0.03535
                }
                endPoint Solid {
                  translation -0.02 -0.03535 0.03535
                  rotation 0 -0.7071067811865476 -0.7071067811865476 5.157247493415652
                  children [
                    USE r8
                  ]
                  name "sr8"
                  boundingObject USE r8
                  physics Physics {
                    density -1
                    mass 0.1
                  }
                }
              }
              USE WHEEL_TRANS
            ]
            boundingObject Pose {
              translation -0.02 0 0
              rotation 0 -1 0 1.5708
              children [
                DEF wheel1 Shape {
                  appearance PBRAppearance {
                    baseColor 0.8 0.8 0.8
                    transparency 0.12999999523162842
                    roughness 1
                    metalness 0
                    emissiveColor 0 1 0
                  }
                  geometry Cylinder {
                    height 0.02
                    radius 0.05
                  }
                }
              ]
            }
            physics Physics {
            }
          }
        }
      ]
      name "wheel 4"
      boundingObject USE DUMMY
      physics Physics {
      }
    }
    Camera {
      translation 0 0 0.4
      rotation 0 1 0 1.5708
      fieldOfView 3.14
      width 640
      height 640
      projection "spherical"
    }
    DEF BODY_TRANS Pose {
      translation 0 0 0.04
      children [
        Shape {
          appearance PBRAppearance {
            baseColor 0.564706 0.933333 0.564706
            roughness 1
            metalness 0
          }
          geometry Box {
            size 0.25 0.25 0.1
          }
        }
      ]
    }
  ]
  name "robot(3)"
  boundingObject USE BODY_TRANS
  physics Physics {
  }
  recognitionColors [
    0 1 0.7
  ]
  controller "my_controller_4"
}
DEF OMNI_WHEELS_4 Robot {
  translation 1.27933 -1.42312 0.06
  rotation 0.0008646924717782624 -2.7749156625345907e-05 0.9999996257683869 0.8373773005898107
  children [
    InertialUnit {
      name "IMU"
    }
    DEF SOLID1 Solid {
      rotation 0 0 1 0.7854003061004253
      children [
        DEF WHEEL1 HingeJoint {
          jointParameters HingeJointParameters {
            position 39.266952503063855
            anchor -0.1 0 0
          }
          device [
            RotationalMotor {
              name "wheel3"
            }
            PositionSensor {
              name "pw3"
            }
          ]
          endPoint Solid {
            translation -0.18799999999756062 -1.2929122714678933e-05 3.872408684111886e-08
            rotation 0.9999999999995569 6.666612978759893e-07 6.646418641983545e-07 1.5678407648645984
            children [
              DEF sr1 HingeJoint {
                jointParameters HingeJointParameters {
                  position -126.31835906130954
                  axis 0 1 0
                  anchor -0.02 0 0.05
                }
                endPoint Solid {
                  translation -0.02 0 0.05
                  rotation 0 -1 0 0.6546529177178064
                  children [
                    DEF r1 Pose {
                      rotation -1 0 0 1.5708
                      children [
                        DEF SMALL_WHEEL_SHAPE Shape {
                          appearance PBRAppearance {
                            baseColor 1 0.752941 0.796078
                            roughness 1
                            metalness 0
                          }
                          geometry Cylinder {
                            height 0.02
                            radius 0.01
                          }
                        }
                      ]
                    }
                  ]
                  name "sr1"
                  boundingObject USE r1
                  physics Physics {
                    density -1
                    mass 0.1
                  }
                }
              }
              DEF sr2 HingeJoint {
                jointParameters HingeJointParameters {
                  position 145.23893767255893
                  axis 0 -0.707107 0.707107
                  anchor -0.02 0.03535 0.03535
                }
                endPoint Solid {
                  translation -0.02 0.03535 0.03535
                  rotation 0 0.7071067811865475 -0.7071067811865475 5.557509699751143
                  children [
                    DEF r2 Pose {
                      rotation -1 0 0 2.27
                      children [
                        USE SMALL_WHEEL_SHAPE
                      ]
                    }
                  ]
                  name "sr2"
                  boundingObject USE r2
                  physics Physics {
                    density -1
                    mass 0.1
                  }
                }
              }
              DEF sr3 HingeJoint {
                jointParameters HingeJointParameters {
                  position 315.6244942672359
                  axis 0 1 0
                  anchor -0.02 0 -0.05
                }
                endPoint Solid {
                  translation -0.02 0 -0.05
                  rotation 0 1 0 1.4652289082565648
                  children [
                    DEF r3 Pose {
                      rotation -1 0 0 1.5708
                      children [
                        USE SMALL_WHEEL_SHAPE
                      ]
                    }
                  ]
                  name "sr3"
                  boundingObject USE r3
                  physics Physics {
                    density -1
                    mass 0.1
                  }
                }
              }
              DEF sr4 HingeJoint {
                jointParameters HingeJointParameters {
                  position -195.38430891061194
                  axis 0 -0.707107 0.707107
                  anchor -0.02 -0.03535 -0.03535
                }
                endPoint Solid {
                  translation -0.02 -0.03535 -0.03535
                  rotation 0 -0.7071067811865475 0.7071067811865475 5.677620919134832
                  children [
                    DEF r4 Pose {
                      rotation -1 0 0 2.27
                      children [
                        USE SMALL_WHEEL_SHAPE
                      ]
                    }
                  ]
                  name "sr4"
                  boundingObject USE r4
                  physics Physics {
                    density -1
                    mass 0.1
                  }
                }
              }
              DEF sr5 HingeJoint {
                jointParameters HingeJointParameters {
                  position 147.55102902190777
                  axis 0 0 1
                  anchor -0.02 0.05 0
                }
                endPoint Solid {
                  translation -0.02 0.05 0
                  rotation 0 0 -1 3.2454183504023093
                  children [
                    DEF r5 Pose {
                      children [
                        USE SMALL_WHEEL_SHAPE
                      ]
                    }
                  ]
                  name "sr5"
                  boundingObject USE r5
                  physics Physics {
                    density -1
                    mass 0.1
                  }
                }
              }
              DEF sr6 HingeJoint {
                jointParameters HingeJointParameters {
                  position -154.2668776251037
                  axis 0 0 1
                  anchor -0.02 -0.05 0
                }
                endPoint Solid {
                  translation -0.02 -0.05 0
                  rotation 0 0 -1 3.4704302527936135
                  children [
                    DEF r6 Pose {
                      children [
                        USE SMALL_WHEEL_SHAPE
                      ]
                    }
                  ]
                  name "sr6"
                  boundingObject USE r6
                  physics Physics {
                    density -1
                    mass 0.1
                  }
                }
              }
              DEF sr7 HingeJoint {
                jointParameters HingeJointParameters {
                  position 179.56148084276518
                  axis 0 0.707107 0.707107
                  anchor -0.02 0.03535 -0.03535
                }
                endPoint Solid {
                  translation -0.02 0.03535 -0.03535
                  rotation 0 0.7071067811865476 0.7071067811865476 3.632292241736757
                  children [
                    DEF r7 Pose {
                      rotation -1 0 0 0.76
                      children [
                        USE SMALL_WHEEL_SHAPE
                      ]
                    }
                  ]
                  name "sr7"
                  boundingObject USE r7
                  physics Physics {
                    density -1
                    mass 0.1
                  }
                }
              }
              DEF sr8 HingeJoint {
                jointParameters HingeJointParameters {
                  position -151.50952450734218
                  axis 0 0.707107 0.707107
                  anchor -0.02 -0.03535 0.03535
                }
                endPoint Solid {
                  translation -0.02 -0.03535 0.03535
                  rotation 0 -0.7071067811865476 -0.7071067811865476 0.7130771350321022
                  children [
                    DEF r8 Pose {
                      rotation -1 0 0 0.76
                      children [
                        USE SMALL_WHEEL_SHAPE
                      ]
                    }
                  ]
                  name "sr8"
                  boundingObject USE r8
                  physics Physics {
                    density -1
                    mass 0.1
                  }
                }
              }
              DEF WHEEL_TRANS Pose {
                translation -0.02 0 0
                rotation 0 -1 0 1.5708
                children [
                  DEF WHEEL_SHAPE Shape {
                    appearance PBRAppearance {
                      baseColor 0.678431 0.847059 0.901961
                      roughness 1
                      metalness 0
                    }
                    geometry Cylinder {
                      height 0.02
                      radius 0.05
                      subdivision 20
                    }
                  }
                ]
              }
            ]
            boundingObject Pose {
              translation -0.02 0 0
              rotation 0 -1 0 1.5708
              children [
                DEF wheel1 Shape {
                  appearance PBRAppearance {
                    baseColor 0.8 0.8 0.8
                    transparency 0.12999999523162842
                    roughness 1
                    metalness 0
                    emissiveColor 0 1 0
                  }
                  geometry Cylinder {
                    height 0.02
                    radius 0.05
                  }
                }
              ]
            }
            physics Physics {
            }
          }
        }
      ]
      name "wheel 1"
      boundingObject DEF DUMMY Sphere {
        radius 0.01
      }
      physics Physics {
      }
    }
    DEF SOLID2 Solid {
      rotation 0 0 1 2.3561996938995744
      children [
        DEF WHEEL2 HingeJoint {
          jointParameters HingeJointParameters {
            position 39.26695940667728
            anchor -0.1 0 0
          }
          device [
            RotationalMotor {
              name "wheel4"
            }
            PositionSensor {
              name "pw4"
            }
          ]
          endPoint Solid {
            translation -0.18800000004308107 -1.288918037647514e-05 3.743020158379229e-08
            rotation 0.999999999999522 6.914781373945531e-07 6.911653715994697e-07 1.5654417141275923
            children [
              DEF sr1 HingeJoint {
                jointParameters HingeJointParameters {
                  position 281.3285552745825
                  axis 0 1 0
                  anchor -0.02 0 0.05
                }
                endPoint Solid {
                  translation -0.02 0 0.05
                  rotation 0 1 0 4.868401758680722
                  children [
                    USE r1
                  ]
                  name "sr1"
                  boundingObject USE r1
                  physics Physics {
                    density -1
                    mass 0.1
                  }
                }
              }
              DEF sr2 HingeJoint {
                jointParameters HingeJointParameters {
                  position -654.5468091978694
                  axis 0 -0.707107 0.707107
                  anchor -0.02 0.03535 0.03535
                }
                endPoint Solid {
                  translation -0.02 0.03535 0.03535
                  rotation 0 0.7071067811865476 -0.7071067811865476 1.0955372511923858
                  children [
                    USE r2
                  ]
                  name "sr2"
                  boundingObject USE r2
                  physics Physics {
                    density -1
                    mass 0.1
                  }
                }
              }
              DEF sr3 HingeJoint {
                jointParameters HingeJointParameters {
                  position -301.8412982122163
                  axis 0 1 0
                  anchor -0.02 0 -0.05
                }
                endPoint Solid {
                  translation -0.02 0 -0.05
                  rotation 0 -1 0 0.24840346759616405
                  children [
                    USE r3
                  ]
                  name "sr3"
                  boundingObject USE r3
                  physics Physics {
                    density -1
                    mass 0.1
                  }
                }
              }
              DEF sr4 HingeJoint {
                jointParameters HingeJointParameters {
                  position 498.1892944275055
                  axis 0 -0.707107 0.707107
                  anchor -0.02 -0.03535 -0.03535
                }
                endPoint Solid {
                  translation -0.02 -0.03535 -0.03535
                  rotation 0 0.7071067811865476 -0.7071067811865476 4.465530146861417
                  children [
                    USE r4
                  ]
                  name "sr4"
                  boundingObject USE r4
                  physics Physics {
                    density -1
                    mass 0.1
                  }
                }
              }
              DEF sr5 HingeJoint {
                jointParameters HingeJointParameters {
                  position -315.6834546224356
                  axis 0 0 1
                  anchor -0.02 0.05 0
                }
                endPoint Solid {
                  translation -0.02 0.05 0
                  rotation 0 0 -1 1.5241892634562664
                  children [
                    USE r5
                  ]
                  name "sr5"
                  boundingObject USE r5
                  physics Physics {
                    density -1
                    mass 0.1
                  }
                }
              }
              DEF sr6 HingeJoint {
                jointParameters HingeJointParameters {
                  position 573.459968285009
                  axis 0 0 1
                  anchor -0.02 -0.05 0
                }
                endPoint Solid {
                  translation -0.02 -0.05 0
                  rotation 0 0 -1 4.593079975512915
                  children [
                    USE r6
                  ]
                  name "sr6"
                  boundingObject USE r6
                  physics Physics {
                    density -1
                    mass 0.1
                  }
                }
              }
              DEF sr7 HingeJoint {
                jointParameters HingeJointParameters {
                  position -638.5444875606736
                  axis 0 0.707107 0.707107
                  anchor -0.02 0.03535 -0.03535
                }
                endPoint Solid {
                  translation -0.02 0.03535 -0.03535
                  rotation 0 0.7071067811865475 0.7071067811865475 2.340413771644233
                  children [
                    USE r7
                  ]
                  name "sr7"
                  boundingObject USE r7
                  physics Physics {
                    density -1
                    mass 0.1
                  }
                }
              }
              DEF sr8 HingeJoint {
                jointParameters HingeJointParameters {
                  position 452.924878582051
                  axis 0 0.707107 0.707107
                  anchor -0.02 -0.03535 0.03535
                }
                endPoint Solid {
                  translation -0.02 -0.03535 0.03535
                  rotation 0 0.7071067811865476 0.7071067811865476 0.5355364651207812
                  children [
                    USE r8
                  ]
                  name "sr8"
                  boundingObject USE r8
                  physics Physics {
                    density -1
                    mass 0.1
                  }
                }
              }
              USE WHEEL_TRANS
            ]
            boundingObject Pose {
              translation -0.02 0 0
              rotation 0 -1 0 1.5708
              children [
                DEF wheel1 Shape {
                  appearance PBRAppearance {
                    baseColor 0.8 0.8 0.8
                    transparency 0.12999999523162842
                    roughness 1
                    metalness 0
                    emissiveColor 0 1 0
                  }
                  geometry Cylinder {
                    height 0.02
                    radius 0.05
                  }
                }
              ]
            }
            physics Physics {
            }
          }
        }
      ]
      name "wheel 2"
      boundingObject USE DUMMY
      physics Physics {
      }
    }
    DEF SOLID3 Solid {
      rotation 0 0 1 -2.3561950010791604
      children [
        DEF WHEEL3 HingeJoint {
          jointParameters HingeJointParameters {
            position -38.62730686243758
            anchor -0.1 0 0
          }
          device [
            PositionSensor {
              name "pw1"
            }
            RotationalMotor {
              name "wheel1"
            }
          ]
          endPoint Solid {
            translation -0.187999999989864 1.0334342591741564e-05 7.735468730047316e-06
            rotation -0.9999999999988193 1.3754176449867172e-06 -6.852057733274673e-07 0.9321031327763781
            children [
              DEF sr1 HingeJoint {
                jointParameters HingeJointParameters {
                  position 210.872298479945
                  axis 0 1 0
                  anchor -0.02 0 0.05
                }
                endPoint Solid {
                  translation -0.02 0 0.05
                  rotation 0 -1 0 2.7560019641609528
                  children [
                    USE r1
                  ]
                  name "sr1"
                  boundingObject USE r1
                  physics Physics {
                    density -1
                    mass 0.1
                  }
                }
              }
              DEF sr2 HingeJoint {
                jointParameters HingeJointParameters {
                  position -524.168522009818
                  axis 0 -0.707107 0.707107
                  anchor -0.02 0.03535 0.03535
                }
                endPoint Solid {
                  translation -0.02 0.03535 0.03535
                  rotation 0 -0.7071067811865476 0.7071067811865476 3.619043793267216
                  children [
                    USE r2
                  ]
                  name "sr2"
                  boundingObject USE r2
                  physics Physics {
                    density -1
                    mass 0.1
                  }
                }
              }
              DEF sr3 HingeJoint {
                jointParameters HingeJointParameters {
                  position -294.03444192748987
                  axis 0 1 0
                  anchor -0.02 0 -0.05
                }
                endPoint Solid {
                  translation -0.02 0 -0.05
                  rotation 0 -0.9999999999999999 0 5.007917797228888
                  children [
                    USE r3
                  ]
                  name "sr3"
                  boundingObject USE r3
                  physics Physics {
                    density -1
                    mass 0.1
                  }
                }
              }
              DEF sr4 HingeJoint {
                jointParameters HingeJointParameters {
                  position 745.1436077755648
                  axis 0 -0.707107 0.707107
                  anchor -0.02 -0.03535 -0.03535
                }
                endPoint Solid {
                  translation -0.02 -0.03535 -0.03535
                  rotation 0 -0.7071067811865475 0.7071067811865475 3.727741528373556
                  children [
                    USE r4
                  ]
                  name "sr4"
                  boundingObject USE r4
                  physics Physics {
                    density -1
                    mass 0.1
                  }
                }
              }
              DEF sr5 HingeJoint {
                jointParameters HingeJointParameters {
                  position -164.32123279850606
                  axis 0 0 1
                  anchor -0.02 0.05 0
                }
                endPoint Solid {
                  translation -0.02 0.05 0
                  rotation 0 0 -1 0.958414811836811
                  children [
                    USE r5
                  ]
                  name "sr5"
                  boundingObject USE r5
                  physics Physics {
                    density -1
                    mass 0.1
                  }
                }
              }
              DEF sr6 HingeJoint {
                jointParameters HingeJointParameters {
                  position 273.9872641320462
                  axis 0 0 1
                  anchor -0.02 -0.05 0
                }
                endPoint Solid {
                  translation -0.02 -0.05 0
                  rotation 0 0 -1 2.472889383855584
                  children [
                    USE r6
                  ]
                  name "sr6"
                  boundingObject USE r6
                  physics Physics {
                    density -1
                    mass 0.1
                  }
                }
              }
              DEF sr7 HingeJoint {
                jointParameters HingeJointParameters {
                  position -337.77185823006744
                  axis 0 0.707107 0.707107
                  anchor -0.02 0.03535 -0.03535
                }
                endPoint Solid {
                  translation -0.02 0.03535 -0.03535
                  rotation 0 0.7071067811865476 0.7071067811865476 1.5201483576302326
                  children [
                    USE r7
                  ]
                  name "sr7"
                  boundingObject USE r7
                  physics Physics {
                    density -1
                    mass 0.1
                  }
                }
              }
              DEF sr8 HingeJoint {
                jointParameters HingeJointParameters {
                  position 337.1902555850693
                  axis 0 0.707107 0.707107
                  anchor -0.02 -0.03535 0.03535
                }
                endPoint Solid {
                  translation -0.02 -0.03535 0.03535
                  rotation 0 -0.7071067811865476 -0.7071067811865476 2.101751002628389
                  children [
                    USE r8
                  ]
                  name "sr8"
                  boundingObject USE r8
                  physics Physics {
                    density -1
                    mass 0.1
                  }
                }
              }
              USE WHEEL_TRANS
            ]
            boundingObject Pose {
              translation -0.02 0 0
              rotation 0 -1 0 1.5708
              children [
                DEF wheel1 Shape {
                  appearance PBRAppearance {
                    baseColor 0.8 0.8 0.8
                    transparency 0.12999999523162842
                    roughness 1
                    metalness 0
                    emissiveColor 0 1 0
                  }
                  geometry Cylinder {
                    height 0.02
                    radius 0.05
                  }
                }
              ]
            }
            physics Physics {
            }
          }
        }
      ]
      name "wheel 3"
      boundingObject USE DUMMY
      physics Physics {
      }
    }
    DEF SOLID4 Solid {
      rotation 0 0 1 -0.7854003061004253
      children [
        DEF WHEEL4 HingeJoint {
          jointParameters HingeJointParameters {
            position -38.62730494897178
            anchor -0.1 0 0
          }
          device [
            PositionSensor {
              name "pw2"
            }
            RotationalMotor {
              name "wheel2"
            }
          ]
          endPoint Solid {
            translation -0.1879999999437038 1.0360237540559678e-05 7.756340433975863e-06
            rotation -0.9999999999988133 1.379020318643372e-06 -6.868437801051039e-07 0.9321012008713594
            children [
              DEF sr1 HingeJoint {
                jointParameters HingeJointParameters {
                  position -118.85385785222414
                  axis 0 1 0
                  anchor -0.02 0 0.05
                }
                endPoint Solid {
                  translation -0.02 0 0.05
                  rotation 0 -1 0 5.756522322991581
                  children [
                    USE r1
                  ]
                  name "sr1"
                  boundingObject USE r1
                  physics Physics {
                    density -1
                    mass 0.1
                  }
                }
              }
              DEF sr2 HingeJoint {
                jointParameters HingeJointParameters {
                  position -173.12609295492786
                  axis 0 -0.707107 0.707107
                  anchor -0.02 0.03535 0.03535
                }
                endPoint Solid {
                  translation -0.02 0.03535 0.03535
                  rotation 0 -0.7071067811865476 0.7071067811865476 2.803095646100566
                  children [
                    USE r2
                  ]
                  name "sr2"
                  boundingObject USE r2
                  physics Physics {
                    density -1
                    mass 0.1
                  }
                }
              }
              DEF sr3 HingeJoint {
                jointParameters HingeJointParameters {
                  position 106.13970904629721
                  axis 0 1 0
                  anchor -0.02 0 -0.05
                }
                endPoint Solid {
                  translation -0.02 0 -0.05
                  rotation 0 1 0 5.60874413142383
                  children [
                    USE r3
                  ]
                  name "sr3"
                  boundingObject USE r3
                  physics Physics {
                    density -1
                    mass 0.1
                  }
                }
              }
              DEF sr4 HingeJoint {
                jointParameters HingeJointParameters {
                  position 342.2477663359929
                  axis 0 -0.707107 0.707107
                  anchor -0.02 -0.03535 -0.03535
                }
                endPoint Solid {
                  translation -0.02 -0.03535 -0.03535
                  rotation 0 -0.7071067811865476 0.7071067811865476 2.9557597482952085
                  children [
                    USE r4
                  ]
                  name "sr4"
                  boundingObject USE r4
                  physics Physics {
                    density -1
                    mass 0.1
                  }
                }
              }
              DEF sr5 HingeJoint {
                jointParameters HingeJointParameters {
                  position 148.49656428673194
                  axis 0 0 1
                  anchor -0.02 0.05 0
                }
                endPoint Solid {
                  translation -0.02 0.05 0
                  rotation 0 0 -1 2.2998830855781365
                  children [
                    USE r5
                  ]
                  name "sr5"
                  boundingObject USE r5
                  physics Physics {
                    density -1
                    mass 0.1
                  }
                }
              }
              DEF sr6 HingeJoint {
                jointParameters HingeJointParameters {
                  position -136.8657522689867
                  axis 0 0 1
                  anchor -0.02 -0.05 0
                }
                endPoint Solid {
                  translation -0.02 -0.05 0
                  rotation 0 0 1 1.3643244889641917
                  children [
                    USE r6
                  ]
                  name "sr6"
                  boundingObject USE r6
                  physics Physics {
                    density -1
                    mass 0.1
                  }
                }
              }
              DEF sr7 HingeJoint {
                jointParameters HingeJointParameters {
                  position 12.543655424733462
                  axis 0 0.707107 0.707107
                  anchor -0.02 0.03535 -0.03535
                }
                endPoint Solid {
                  translation -0.02 0.03535 -0.03535
                  rotation 0 -0.7071067811865476 -0.7071067811865476 0.02271518962571068
                  children [
                    USE r7
                  ]
                  name "sr7"
                  boundingObject USE r7
                  physics Physics {
                    density -1
                    mass 0.1
                  }
                }
              }
              DEF sr8 HingeJoint {
                jointParameters HingeJointParameters {
                  position -30.289988722133998
                  axis 0 0.707107 0.707107
                  anchor -0.02 -0.03535 0.03535
                }
                endPoint Solid {
                  translation -0.02 -0.03535 0.03535
                  rotation 0 -0.7071067811865476 -0.7071067811865476 5.157247493415652
                  children [
                    USE r8
                  ]
                  name "sr8"
                  boundingObject USE r8
                  physics Physics {
                    density -1
                    mass 0.1
                  }
                }
              }
              USE WHEEL_TRANS
            ]
            boundingObject Pose {
              translation -0.02 0 0
              rotation 0 -1 0 1.5708
              children [
                DEF wheel1 Shape {
                  appearance PBRAppearance {
                    baseColor 0.8 0.8 0.8
                    transparency 0.12999999523162842
                    roughness 1
                    metalness 0
                    emissiveColor 0 1 0
                  }
                  geometry Cylinder {
                    height 0.02
                    radius 0.05
                  }
                }
              ]
            }
            physics Physics {
            }
          }
        }
      ]
      name "wheel 4"
      boundingObject USE DUMMY
      physics Physics {
      }
    }
    Camera {
      translation 0 0 0.4
      rotation 0 1 0 1.5708
      fieldOfView 3.14
      width 640
      height 640
      projection "spherical"
    }
    DEF BODY_TRANS Pose {
      translation 0 0 0.04
      children [
        Shape {
          appearance PBRAppearance {
            baseColor 0.564706 0.933333 0.564706
            roughness 1
            metalness 0
          }
          geometry Box {
            size 0.25 0.25 0.1
          }
        }
      ]
    }
  ]
  name "robot(1)"
  boundingObject USE BODY_TRANS
  physics Physics {
  }
  recognitionColors [
    0 1 0.7
  ]
  controller "my_controller_4"
}
DEF OMNI_WHEELS Robot {
  translation 0 0 0.0685135
  children [
    InertialUnit {
      name "IMU"
    }
    DEF SOLID1 Solid {
      children [
        DEF WHEEL1 HingeJoint {
          jointParameters HingeJointParameters {
            anchor -0.1 0 0
          }
          device [
            RotationalMotor {
              name "wheel2"
              maxVelocity 40
            }
            PositionSensor {
              name "pw2"
            }
          ]
          endPoint Solid {
            translation -0.18800000000000017 0 0
            rotation 1 0 0 0
            children [
              DEF sr1 HingeJoint {
                jointParameters HingeJointParameters {
                  position 57.818923725650066
                  axis 0 1 0
                  anchor -0.02 0 0.05
                }
                endPoint Solid {
                  translation -0.02 0 0.05
                  rotation 0 -1 0 5.012929346145799
                  children [
                    DEF r1 Pose {
                      rotation -1 0 0 1.5708
                      children [
                        DEF SMALL_WHEEL_SHAPE Shape {
                          appearance PBRAppearance {
                            baseColor 1 0.752941 0.796078
                            roughness 1
                            metalness 0
                          }
                          geometry Cylinder {
                            height 0.02
                            radius 0.01
                          }
                        }
                      ]
                    }
                  ]
                  name "sr1"
                  boundingObject USE r1
                  physics Physics {
                    density -1
                    mass 0.1
                  }
                }
              }
              DEF sr2 HingeJoint {
                jointParameters HingeJointParameters {
                  position -72.88005372569901
                  axis 0 -0.707107 0.707107
                  anchor -0.02 0.03535 0.03535
                }
                endPoint Solid {
                  translation -0.02 0.03535 0.03535
                  rotation 0 -0.7071067811865476 0.7071067811865476 2.518169960456024
                  children [
                    DEF r2 Pose {
                      rotation -1 0 0 2.27
                      children [
                        USE SMALL_WHEEL_SHAPE
                      ]
                    }
                  ]
                  name "sr2"
                  boundingObject USE r2
                  physics Physics {
                    density -1
                    mass 0.1
                  }
                }
              }
              DEF sr3 HingeJoint {
                jointParameters HingeJointParameters {
                  position 254.04620295298855
                  axis 0 1 0
                  anchor -0.02 0 -0.05
                }
                endPoint Solid {
                  translation -0.02 0 -0.05
                  rotation 0 1 0 2.718790665805092
                  children [
                    DEF r3 Pose {
                      rotation -1 0 0 1.5708
                      children [
                        USE SMALL_WHEEL_SHAPE
                      ]
                    }
                  ]
                  name "sr3"
                  boundingObject USE r3
                  physics Physics {
                    density -1
                    mass 0.1
                  }
                }
              }
              DEF sr4 HingeJoint {
                jointParameters HingeJointParameters {
                  position -91.47881405216481
                  axis 0 -0.707107 0.707107
                  anchor -0.02 -0.03535 -0.03535
                }
                endPoint Solid {
                  translation -0.02 -0.03535 -0.03535
                  rotation 0 0.7071067811865475 -0.7071067811865475 3.5142197516505966
                  children [
                    DEF r4 Pose {
                      rotation -1 0 0 2.27
                      children [
                        USE SMALL_WHEEL_SHAPE
                      ]
                    }
                  ]
                  name "sr4"
                  boundingObject USE r4
                  physics Physics {
                    density -1
                    mass 0.1
                  }
                }
              }
              DEF sr5 HingeJoint {
                jointParameters HingeJointParameters {
                  position -57.772264993484754
                  axis 0 0 1
                  anchor -0.02 0.05 0
                }
                endPoint Solid {
                  translation -0.02 0.05 0
                  rotation 0 0 1 5.059588078311111
                  children [
                    DEF r5 Pose {
                      children [
                        USE SMALL_WHEEL_SHAPE
                      ]
                    }
                  ]
                  name "sr5"
                  boundingObject USE r5
                  physics Physics {
                    density -1
                    mass 0.1
                  }
                }
              }
              DEF sr6 HingeJoint {
                jointParameters HingeJointParameters {
                  position 29.313257184556182
                  axis 0 0 1
                  anchor -0.02 -0.05 0
                }
                endPoint Solid {
                  translation -0.02 -0.05 0
                  rotation 0 0 1 4.180515955837836
                  children [
                    DEF r6 Pose {
                      children [
                        USE SMALL_WHEEL_SHAPE
                      ]
                    }
                  ]
                  name "sr6"
                  boundingObject USE r6
                  physics Physics {
                    density -1
                    mass 0.1
                  }
                }
              }
              DEF sr7 HingeJoint {
                jointParameters HingeJointParameters {
                  position -30.271312436053034
                  axis 0 0.707107 0.707107
                  anchor -0.02 0.03535 -0.03535
                }
                endPoint Solid {
                  translation -0.02 0.03535 -0.03535
                  rotation 0 -0.7071067811865476 -0.7071067811865476 5.138571207334688
                  children [
                    DEF r7 Pose {
                      rotation -1 0 0 0.76
                      children [
                        USE SMALL_WHEEL_SHAPE
                      ]
                    }
                  ]
                  name "sr7"
                  boundingObject USE r7
                  physics Physics {
                    density -1
                    mass 0.1
                  }
                }
              }
              DEF sr8 HingeJoint {
                jointParameters HingeJointParameters {
                  position 43.76009834491514
                  axis 0 0.707107 0.707107
                  anchor -0.02 -0.03535 0.03535
                }
                endPoint Solid {
                  translation -0.02 -0.03535 0.03535
                  rotation 0 0.7071067811865476 0.7071067811865476 6.060986501837623
                  children [
                    DEF r8 Pose {
                      rotation -1 0 0 0.76
                      children [
                        USE SMALL_WHEEL_SHAPE
                      ]
                    }
                  ]
                  name "sr8"
                  boundingObject USE r8
                  physics Physics {
                    density -1
                    mass 0.1
                  }
                }
              }
              DEF WHEEL_TRANS Pose {
                translation -0.02 0 0
                rotation 0 -1 0 1.5708
                children [
                  DEF WHEEL_SHAPE Shape {
                    appearance PBRAppearance {
                      baseColor 0.678431 0.847059 0.901961
                      roughness 1
                      metalness 0
                    }
                    geometry Cylinder {
                      height 0.02
                      radius 0.05
                      subdivision 20
                    }
                  }
                ]
              }
            ]
            boundingObject Pose {
              translation -0.02 0 0
              rotation 0 -1 0 1.5708
              children [
                DEF wheel1 Shape {
                  appearance PBRAppearance {
                    baseColor 0.8 0.8 0.8
                    transparency 0.12999999523162842
                    roughness 1
                    metalness 0
                    emissiveColor 0 1 0
                  }
                  geometry Cylinder {
                    height 0.02
                    radius 0.05
                  }
                }
              ]
            }
            physics Physics {
            }
          }
        }
      ]
      name "wheel 1"
      boundingObject DEF DUMMY Sphere {
        radius 0.01
      }
      physics Physics {
      }
    }
    DEF SOLID2 Solid {
      rotation 0 0 1 2.09
      children [
        DEF WHEEL2 HingeJoint {
          jointParameters HingeJointParameters {
            anchor -0.1 0 0
          }
          device [
            RotationalMotor {
              name "wheel3"
              maxVelocity 40
            }
            PositionSensor {
              name "pw3"
            }
          ]
          endPoint Solid {
            translation -0.188 0 0
            rotation -1 0 0 0.002405809965994725
            children [
              DEF sr1 HingeJoint {
                jointParameters HingeJointParameters {
                  position 197.25553266959355
                  axis 0 1 0
                  anchor -0.02 0 0.05
                }
                endPoint Solid {
                  translation -0.02 0 0.05
                  rotation 0 -0.9999999999999999 0 3.8063971601532183
                  children [
                    USE r1
                  ]
                  name "sr1"
                  boundingObject USE r1
                  physics Physics {
                    density -1
                    mass 0.1
                  }
                }
              }
              DEF sr2 HingeJoint {
                jointParameters HingeJointParameters {
                  position -547.5878807610936
                  axis 0 -0.707107 0.707107
                  anchor -0.02 0.03535 0.03535
                }
                endPoint Solid {
                  translation -0.02 0.03535 0.03535
                  rotation 0 -0.7071067811865475 0.7071067811865475 5.3324262707099805
                  children [
                    USE r2
                  ]
                  name "sr2"
                  boundingObject USE r2
                  physics Physics {
                    density -1
                    mass 0.1
                  }
                }
              }
              DEF sr3 HingeJoint {
                jointParameters HingeJointParameters {
                  position -202.89835579489755
                  axis 0 1 0
                  anchor -0.02 0 -0.05
                }
                endPoint Solid {
                  translation -0.02 0 -0.05
                  rotation 0 -1 0 1.836425965150787
                  children [
                    USE r3
                  ]
                  name "sr3"
                  boundingObject USE r3
                  physics Physics {
                    density -1
                    mass 0.1
                  }
                }
              }
              DEF sr4 HingeJoint {
                jointParameters HingeJointParameters {
                  position 416.0460355104672
                  axis 0 -0.707107 0.707107
                  anchor -0.02 -0.03535 -0.03535
                }
                endPoint Solid {
                  translation -0.02 -0.03535 -0.03535
                  rotation 0 -0.7071067811865476 0.7071067811865476 1.355805236614513
                  children [
                    USE r4
                  ]
                  name "sr4"
                  boundingObject USE r4
                  physics Physics {
                    density -1
                    mass 0.1
                  }
                }
              }
              DEF sr5 HingeJoint {
                jointParameters HingeJointParameters {
                  position -218.72698461420208
                  axis 0 0 1
                  anchor -0.02 0.05 0
                }
                endPoint Solid {
                  translation -0.02 0.05 0
                  rotation 0 0 -1 5.098684170096141
                  children [
                    USE r5
                  ]
                  name "sr5"
                  boundingObject USE r5
                  physics Physics {
                    density -1
                    mass 0.1
                  }
                }
              }
              DEF sr6 HingeJoint {
                jointParameters HingeJointParameters {
                  position 508.15491425342253
                  axis 0 0 1
                  anchor -0.02 -0.05 0
                }
                endPoint Solid {
                  translation -0.02 -0.05 0
                  rotation 0 0 1 5.500089679055614
                  children [
                    USE r6
                  ]
                  name "sr6"
                  boundingObject USE r6
                  physics Physics {
                    density -1
                    mass 0.1
                  }
                }
              }
              DEF sr7 HingeJoint {
                jointParameters HingeJointParameters {
                  position -590.1584457261348
                  axis 0 0.707107 0.707107
                  anchor -0.02 0.03535 -0.03535
                }
                endPoint Solid {
                  translation -0.02 0.03535 -0.03535
                  rotation 0 0.7071067811865475 0.7071067811865475 0.46097314874632783
                  children [
                    USE r7
                  ]
                  name "sr7"
                  boundingObject USE r7
                  physics Physics {
                    density -1
                    mass 0.1
                  }
                }
              }
              DEF sr8 HingeJoint {
                jointParameters HingeJointParameters {
                  position 364.15016465483393
                  axis 0 0.707107 0.707107
                  anchor -0.02 -0.03535 0.03535
                }
                endPoint Solid {
                  translation -0.02 -0.03535 0.03535
                  rotation 0 -0.7071067811865475 -0.7071067811865475 0.2745831615820854
                  children [
                    USE r8
                  ]
                  name "sr8"
                  boundingObject USE r8
                  physics Physics {
                    density -1
                    mass 0.1
                  }
                }
              }
              USE WHEEL_TRANS
            ]
            boundingObject Pose {
              translation -0.02 0 0
              rotation 0 -1 0 1.5708
              children [
                DEF wheel1 Shape {
                  appearance PBRAppearance {
                    baseColor 0.8 0.8 0.8
                    transparency 0.12999999523162842
                    roughness 1
                    metalness 0
                    emissiveColor 0 1 0
                  }
                  geometry Cylinder {
                    height 0.02
                    radius 0.05
                  }
                }
              ]
            }
            physics Physics {
            }
          }
        }
      ]
      name "wheel 2"
      boundingObject USE DUMMY
      physics Physics {
      }
    }
    DEF SOLID3 Solid {
      rotation 0 0 1 -2.093185307179586
      children [
        DEF WHEEL3 HingeJoint {
          jointParameters HingeJointParameters {
            anchor -0.1 0 0
          }
          device [
            PositionSensor {
              name "pw1"
            }
            RotationalMotor {
              name "wheel1"
              maxVelocity 40
            }
          ]
          endPoint Solid {
            translation -0.1880000000000005 0 0
            rotation -1 0 0 0.003909439977756379
            children [
              DEF sr1 HingeJoint {
                jointParameters HingeJointParameters {
                  position 104.94497623953374
                  axis 0 1 0
                  anchor -0.02 0 0.05
                }
                endPoint Solid {
                  translation -0.02 0 0.05
                  rotation 0 1 0 4.41401132466036
                  children [
                    USE r1
                  ]
                  name "sr1"
                  boundingObject USE r1
                  physics Physics {
                    density -1
                    mass 0.1
                  }
                }
              }
              DEF sr2 HingeJoint {
                jointParameters HingeJointParameters {
                  position -407.5530596520016
                  axis 0 -0.707107 0.707107
                  anchor -0.02 0.03535 0.03535
                }
                endPoint Solid {
                  translation -0.02 0.03535 0.03535
                  rotation 0 0.7071067811865475 -0.7071067811865475 5.4291999925080585
                  children [
                    USE r2
                  ]
                  name "sr2"
                  boundingObject USE r2
                  physics Physics {
                    density -1
                    mass 0.1
                  }
                }
              }
              DEF sr3 HingeJoint {
                jointParameters HingeJointParameters {
                  position -171.4732015421863
                  axis 0 1 0
                  anchor -0.02 0 -0.05
                }
                endPoint Solid {
                  translation -0.02 0 -0.05
                  rotation 0 1 0 4.455987058842119
                  children [
                    USE r3
                  ]
                  name "sr3"
                  boundingObject USE r3
                  physics Physics {
                    density -1
                    mass 0.1
                  }
                }
              }
              DEF sr4 HingeJoint {
                jointParameters HingeJointParameters {
                  position 600.9425829994175
                  axis 0 -0.707107 0.707107
                  anchor -0.02 -0.03535 -0.03535
                }
                endPoint Solid {
                  translation -0.02 -0.03535 -0.03535
                  rotation 0 0.7071067811865476 -0.7071067811865476 2.24320648982282
                  children [
                    USE r4
                  ]
                  name "sr4"
                  boundingObject USE r4
                  physics Physics {
                    density -1
                    mass 0.1
                  }
                }
              }
              DEF sr5 HingeJoint {
                jointParameters HingeJointParameters {
                  position -68.43711455286427
                  axis 0 0 1
                  anchor -0.02 0.05 0
                }
                endPoint Solid {
                  translation -0.02 0.05 0
                  rotation 0 0 -1 5.605261481068408
                  children [
                    USE r5
                  ]
                  name "sr5"
                  boundingObject USE r5
                  physics Physics {
                    density -1
                    mass 0.1
                  }
                }
              }
              DEF sr6 HingeJoint {
                jointParameters HingeJointParameters {
                  position 131.25936804518935
                  axis 0 0 1
                  anchor -0.02 -0.05 0
                }
                endPoint Solid {
                  translation -0.02 -0.05 0
                  rotation 0 0 0.9999999999999999 5.595661901597619
                  children [
                    USE r6
                  ]
                  name "sr6"
                  boundingObject USE r6
                  physics Physics {
                    density -1
                    mass 0.1
                  }
                }
              }
              DEF sr7 HingeJoint {
                jointParameters HingeJointParameters {
                  position -233.19248290411932
                  axis 0 0.707107 0.707107
                  anchor -0.02 0.03535 -0.03535
                }
                endPoint Solid {
                  translation -0.02 0.03535 -0.03535
                  rotation 0 0.7071067811865475 0.7071067811865475 5.568558768704969
                  children [
                    USE r7
                  ]
                  name "sr7"
                  boundingObject USE r7
                  physics Physics {
                    density -1
                    mass 0.1
                  }
                }
              }
              DEF sr8 HingeJoint {
                jointParameters HingeJointParameters {
                  position 203.553516850033
                  axis 0 0.707107 0.707107
                  anchor -0.02 -0.03535 0.03535
                }
                endPoint Solid {
                  translation -0.02 -0.03535 0.03535
                  rotation 0 0.7071067811865476 0.7071067811865476 2.4915870202862243
                  children [
                    USE r8
                  ]
                  name "sr8"
                  boundingObject USE r8
                  physics Physics {
                    density -1
                    mass 0.1
                  }
                }
              }
              USE WHEEL_TRANS
            ]
            boundingObject Pose {
              translation -0.02 0 0
              rotation 0 -1 0 1.5708
              children [
                DEF wheel1 Shape {
                  appearance PBRAppearance {
                    baseColor 0.8 0.8 0.8
                    transparency 0.12999999523162842
                    roughness 1
                    metalness 0
                    emissiveColor 0 1 0
                  }
                  geometry Cylinder {
                    height 0.02
                    radius 0.05
                  }
                }
              ]
            }
            physics Physics {
            }
          }
        }
      ]
      name "wheel 3"
      boundingObject USE DUMMY
      physics Physics {
      }
    }
    Camera {
      translation 0 0 0.4
      rotation 0 1 0 1.5708
      fieldOfView 3.14
      width 640
      height 640
      projection "spherical"
      recognition Recognition {
        maxRange 200
        frameColor 0 1 0.7
        frameThickness 3
      }
    }
    DEF BODY_TRANS Pose {
      translation 0 0 0.03
      children [
        Shape {
          appearance PBRAppearance {
            baseColor 0.564706 0.933333 0.564706
            roughness 1
            metalness 0
          }
          geometry Cylinder {
            height 0.15
            radius 0.18
            subdivision 18
          }
        }
      ]
    }
  ]
  boundingObject USE BODY_TRANS
  physics Physics {
  }
  recognitionColors [
    0 1 0.7
  ]
  controller "my_controller"
}
